<?xml version="1.0" ?>
<robot name="asc_robot" xmlns:xacro="http://www.ros.org/wiki/xacro">

<xacro:include filename="$(find asc_robot_description)/urdf/materials.xacro" />
<xacro:include filename="$(find asc_robot_description)/urdf/asc_robot.trans" />
<xacro:include filename="$(find asc_robot_description)/urdf/asc_robot.gazebo" />
<link name="base_link">
  <inertial>
    <origin xyz="0.030721038390233324 -2.4231983503374707e-17 0.09610116641875463" rpy="0 0 0"/>
    <mass value="4.804201101025099"/>
    <inertia ixx="0.020655" iyy="0.034805" izz="0.04017" ixy="-0.0" iyz="-0.0" ixz="-0.000225"/>
  </inertial>
  <visual>
    <origin xyz="0 0 0" rpy="0 0 0"/>
    <geometry>
      <mesh filename="package://asc_robot_description/meshes/base_link.stl" scale="0.001 0.001 0.001"/>
    </geometry>
    <material name="silver"/>
  </visual>
  <collision>
    <origin xyz="0 0 0" rpy="0 0 0"/>
    <geometry>
      <mesh filename="package://asc_robot_description/meshes/base_link.stl" scale="0.001 0.001 0.001"/>
    </geometry>
  </collision>
</link>

<link name="left_wheel_1">
  <inertial>
    <origin xyz="5.551115123125783e-17 0.014499999999999985 8.326672684688674e-17" rpy="0 0 0"/>
    <mass value="0.2379263942673854"/>
    <inertia ixx="0.000395" iyy="0.000757" izz="0.000395" ixy="0.0" iyz="-0.0" ixz="0.0"/>
  </inertial>
  <visual>
    <origin xyz="-0.095 -0.0945 -0.072" rpy="0 0 0"/>
    <geometry>
      <mesh filename="package://asc_robot_description/meshes/left_wheel_1.stl" scale="0.001 0.001 0.001"/>
    </geometry>
    <material name="black"/>
  </visual>
  <collision>
    <origin xyz="-0.095 -0.0945 -0.072" rpy="0 0 0"/>
    <geometry>
      <mesh filename="package://asc_robot_description/meshes/left_wheel_1.stl" scale="0.001 0.001 0.001"/>
    </geometry>
  </collision>
</link>

<link name="right_wheel_1">
  <inertial>
    <origin xyz="1.1102230246251565e-16 -0.014499999999999999 5.551115123125783e-17" rpy="0 0 0"/>
    <mass value="0.2379263942673856"/>
    <inertia ixx="0.000395" iyy="0.000757" izz="0.000395" ixy="0.0" iyz="-0.0" ixz="0.0"/>
  </inertial>
  <visual>
    <origin xyz="-0.095 0.0945 -0.072" rpy="0 0 0"/>
    <geometry>
      <mesh filename="package://asc_robot_description/meshes/right_wheel_1.stl" scale="0.001 0.001 0.001"/>
    </geometry>
    <material name="black"/>
  </visual>
  <collision>
    <origin xyz="-0.095 0.0945 -0.072" rpy="0 0 0"/>
    <geometry>
      <mesh filename="package://asc_robot_description/meshes/right_wheel_1.stl" scale="0.001 0.001 0.001"/>
    </geometry>
  </collision>
</link>

<link name="Lidar_1">
  <inertial>
    <origin xyz="-2.0816681711721685e-17 0.0 0.009999999999999981" rpy="0 0 0"/>
    <mass value="0.08252224998388268"/>
    <inertia ixx="2.8e-05" iyy="2.8e-05" izz="5.1e-05" ixy="-0.0" iyz="0.0" ixz="-0.0"/>
  </inertial>
  <visual>
    <origin xyz="-0.034 -0.0 -0.178" rpy="0 0 0"/>
    <geometry>
      <mesh filename="package://asc_robot_description/meshes/Lidar_1.stl" scale="0.001 0.001 0.001"/>
    </geometry>
    <material name="blue"/>
  </visual>
  <collision>
    <origin xyz="-0.034 -0.0 -0.178" rpy="0 0 0"/>
    <geometry>
      <mesh filename="package://asc_robot_description/meshes/Lidar_1.stl" scale="0.001 0.001 0.001"/>
    </geometry>
  </collision>
</link>

<link name="Pan_1">
  <inertial>
    <origin xyz="-0.0033016845833761035 1.5400658143278853e-18 0.019733744288745192" rpy="0 0 0"/>
    <mass value="0.03287273144557227"/>
    <inertia ixx="3e-06" iyy="8e-06" izz="7e-06" ixy="-0.0" iyz="-0.0" ixz="0.0"/>
  </inertial>
  <visual>
    <origin xyz="-0.054 -0.0 -0.2365" rpy="0 0 0"/>
    <geometry>
      <mesh filename="package://asc_robot_description/meshes/Pan_1.stl" scale="0.001 0.001 0.001"/>
    </geometry>
    <material name="white"/>
  </visual>
  <collision>
    <origin xyz="-0.054 -0.0 -0.2365" rpy="0 0 0"/>
    <geometry>
      <mesh filename="package://asc_robot_description/meshes/Pan_1.stl" scale="0.001 0.001 0.001"/>
    </geometry>
  </collision>
</link>

<link name="Tilt_1">
  <inertial>
    <origin xyz="-6.938893903907228e-18 -0.009999999999999995 0.02848186459510249" rpy="0 0 0"/>
    <mass value="0.03969192382841363"/>
    <inertia ixx="3.7e-05" iyy="2.4e-05" izz="1.5e-05" ixy="0.0" iyz="-0.0" ixz="-0.0"/>
  </inertial>
  <visual>
    <origin xyz="-0.034 -0.01 -0.259" rpy="0 0 0"/>
    <geometry>
      <mesh filename="package://asc_robot_description/meshes/Tilt_1.stl" scale="0.001 0.001 0.001"/>
    </geometry>
    <material name="silver"/>
  </visual>
  <collision>
    <origin xyz="-0.034 -0.01 -0.259" rpy="0 0 0"/>
    <geometry>
      <mesh filename="package://asc_robot_description/meshes/Tilt_1.stl" scale="0.001 0.001 0.001"/>
    </geometry>
  </collision>
</link>

<link name="Camera_1">
  <inertial>
    <origin xyz="0.002500000000000009 4.44089209850061e-18 0.0" rpy="0 0 0"/>
    <mass value="0.00276000000000001"/>
    <inertia ixx="0.0" iyy="0.0" izz="0.0" ixy="0.0" iyz="-0.0" ixz="0.0"/>
  </inertial>
  <visual>
    <origin xyz="-0.044 -0.0 -0.319" rpy="0 0 0"/>
    <geometry>
      <mesh filename="package://asc_robot_description/meshes/Camera_1.stl" scale="0.001 0.001 0.001"/>
    </geometry>
    <material name="red"/>
  </visual>
  <collision>
    <origin xyz="-0.044 -0.0 -0.319" rpy="0 0 0"/>
    <geometry>
      <mesh filename="package://asc_robot_description/meshes/Camera_1.stl" scale="0.001 0.001 0.001"/>
    </geometry>
  </collision>
</link>

<joint name="left_rev" type="continuous">
  <origin xyz="0.095 0.0945 0.072" rpy="0 0 0"/>
  <parent link="base_link"/>
  <child link="left_wheel_1"/>
  <axis xyz="0.0 1.0 0.0"/>
</joint>

<joint name="right_rev" type="continuous">
  <origin xyz="0.095 -0.0945 0.072" rpy="0 0 0"/>
  <parent link="base_link"/>
  <child link="right_wheel_1"/>
  <axis xyz="0.0 1.0 0.0"/>
</joint>

<joint name="lidar_stick" type="fixed">
  <origin xyz="0.034 0.0 0.178" rpy="0 0 0"/>
  <parent link="base_link"/>
  <child link="Lidar_1"/>
</joint>

<joint name="pan_rev" type="fixed">
  <origin xyz="0.054 0.0 0.2365" rpy="0 0 0"/>
  <parent link="base_link"/>
  <child link="Pan_1"/>
  <axis xyz="0.0 0.0 1.0"/>
</joint>

<joint name="tilt_rev" type="fixed">
  <origin xyz="-0.02 0.01 0.0225" rpy="0 0 0"/>
  <parent link="Pan_1"/>
  <child link="Tilt_1"/>
  <axis xyz="0.0 1.0 0.0"/>
</joint>

<joint name="cam_stick" type="fixed">
  <origin xyz="0.01 -0.01 0.06" rpy="0 0 0"/>
  <parent link="Tilt_1"/>
  <child link="Camera_1"/>
</joint>

</robot>
